[2023-09-17T19:12:54.205+0000] {taskinstance.py:1083} INFO - Dependencies all met for <TaskInstance: your_python_dag.load_data_task manual__2023-09-17T19:12:51.381963+00:00 [queued]>
[2023-09-17T19:12:54.219+0000] {taskinstance.py:1083} INFO - Dependencies all met for <TaskInstance: your_python_dag.load_data_task manual__2023-09-17T19:12:51.381963+00:00 [queued]>
[2023-09-17T19:12:54.220+0000] {taskinstance.py:1279} INFO - 
--------------------------------------------------------------------------------
[2023-09-17T19:12:54.220+0000] {taskinstance.py:1280} INFO - Starting attempt 1 of 1
[2023-09-17T19:12:54.220+0000] {taskinstance.py:1281} INFO - 
--------------------------------------------------------------------------------
[2023-09-17T19:12:54.234+0000] {taskinstance.py:1300} INFO - Executing <Task(PythonOperator): load_data_task> on 2023-09-17 19:12:51.381963+00:00
[2023-09-17T19:12:54.246+0000] {standard_task_runner.py:55} INFO - Started process 3258 to run task
[2023-09-17T19:12:54.252+0000] {standard_task_runner.py:82} INFO - Running: ['***', 'tasks', 'run', 'your_python_dag', 'load_data_task', 'manual__2023-09-17T19:12:51.381963+00:00', '--job-id', '46', '--raw', '--subdir', 'DAGS_FOLDER/***.py', '--cfg-path', '/tmp/tmpryxx12du']
[2023-09-17T19:12:54.265+0000] {standard_task_runner.py:83} INFO - Job 46: Subtask load_data_task
[2023-09-17T19:12:54.376+0000] {task_command.py:388} INFO - Running <TaskInstance: your_python_dag.load_data_task manual__2023-09-17T19:12:51.381963+00:00 [running]> on host 80c059a34b8e
[2023-09-17T19:12:54.460+0000] {taskinstance.py:1509} INFO - Exporting the following env vars:
AIRFLOW_CTX_DAG_OWNER=your_name
AIRFLOW_CTX_DAG_ID=your_python_dag
AIRFLOW_CTX_TASK_ID=load_data_task
AIRFLOW_CTX_EXECUTION_DATE=2023-09-17T19:12:51.381963+00:00
AIRFLOW_CTX_TRY_NUMBER=1
AIRFLOW_CTX_DAG_RUN_ID=manual__2023-09-17T19:12:51.381963+00:00
[2023-09-17T19:12:54.461+0000] {taskinstance.py:1768} ERROR - Task failed with exception
Traceback (most recent call last):
  File "/home/airflow/.local/lib/python3.7/site-packages/airflow/operators/python.py", line 175, in execute
    return_value = self.execute_callable()
  File "/home/airflow/.local/lib/python3.7/site-packages/airflow/operators/python.py", line 192, in execute_callable
    return self.python_callable(*self.op_args, **self.op_kwargs)
  File "/opt/airflow/dags/src/lab2.py", line 17, in load_data
    os.chdir("../src")
NameError: name 'os' is not defined
[2023-09-17T19:12:54.474+0000] {taskinstance.py:1323} INFO - Marking task as FAILED. dag_id=your_python_dag, task_id=load_data_task, execution_date=20230917T191251, start_date=20230917T191254, end_date=20230917T191254
[2023-09-17T19:12:54.485+0000] {standard_task_runner.py:105} ERROR - Failed to execute job 46 for task load_data_task (name 'os' is not defined; 3258)
[2023-09-17T19:12:54.505+0000] {local_task_job.py:208} INFO - Task exited with return code 1
[2023-09-17T19:12:54.540+0000] {taskinstance.py:2578} INFO - 0 downstream tasks scheduled from follow-on schedule check
