[2023-09-17T19:56:09.539+0000] {taskinstance.py:1083} INFO - Dependencies all met for <TaskInstance: your_python_dag.data_preprocessing_task manual__2023-09-17T19:56:03.716141+00:00 [queued]>
[2023-09-17T19:56:09.547+0000] {taskinstance.py:1083} INFO - Dependencies all met for <TaskInstance: your_python_dag.data_preprocessing_task manual__2023-09-17T19:56:03.716141+00:00 [queued]>
[2023-09-17T19:56:09.547+0000] {taskinstance.py:1279} INFO - 
--------------------------------------------------------------------------------
[2023-09-17T19:56:09.548+0000] {taskinstance.py:1280} INFO - Starting attempt 1 of 1
[2023-09-17T19:56:09.548+0000] {taskinstance.py:1281} INFO - 
--------------------------------------------------------------------------------
[2023-09-17T19:56:09.558+0000] {taskinstance.py:1300} INFO - Executing <Task(PythonOperator): data_preprocessing_task> on 2023-09-17 19:56:03.716141+00:00
[2023-09-17T19:56:09.568+0000] {standard_task_runner.py:55} INFO - Started process 5716 to run task
[2023-09-17T19:56:09.575+0000] {standard_task_runner.py:82} INFO - Running: ['***', 'tasks', 'run', 'your_python_dag', 'data_preprocessing_task', 'manual__2023-09-17T19:56:03.716141+00:00', '--job-id', '75', '--raw', '--subdir', 'DAGS_FOLDER/***.py', '--cfg-path', '/tmp/tmpko3va8vt']
[2023-09-17T19:56:09.579+0000] {standard_task_runner.py:83} INFO - Job 75: Subtask data_preprocessing_task
[2023-09-17T19:56:09.769+0000] {task_command.py:388} INFO - Running <TaskInstance: your_python_dag.data_preprocessing_task manual__2023-09-17T19:56:03.716141+00:00 [running]> on host 80c059a34b8e
[2023-09-17T19:56:09.988+0000] {taskinstance.py:1509} INFO - Exporting the following env vars:
AIRFLOW_CTX_DAG_OWNER=your_name
AIRFLOW_CTX_DAG_ID=your_python_dag
AIRFLOW_CTX_TASK_ID=data_preprocessing_task
AIRFLOW_CTX_EXECUTION_DATE=2023-09-17T19:56:03.716141+00:00
AIRFLOW_CTX_TRY_NUMBER=1
AIRFLOW_CTX_DAG_RUN_ID=manual__2023-09-17T19:56:03.716141+00:00
[2023-09-17T19:56:09.990+0000] {logging_mixin.py:137} INFO - <class 'str'>
[2023-09-17T19:56:09.990+0000] {logging_mixin.py:137} INFO - ahbd
[2023-09-17T19:56:09.991+0000] {logging_mixin.py:137} INFO -      CUST_ID      BALANCE  ...  PRC_FULL_PAYMENT  TENURE
0     C10001    40.900749  ...          0.000000      12
1     C10002  3202.467416  ...          0.222222      12
2     C10003  2495.148862  ...          0.000000      12
3     C10004  1666.670542  ...          0.000000      12
4     C10005   817.714335  ...          0.000000      12
...      ...          ...  ...               ...     ...
8945  C19186    28.493517  ...          0.500000       6
8946  C19187    19.183215  ...          0.000000       6
8947  C19188    23.398673  ...          0.250000       6
8948  C19189    13.457564  ...          0.250000       6
8949  C19190   372.708075  ...          0.000000       6

[8950 rows x 18 columns]
[2023-09-17T19:56:09.997+0000] {logging_mixin.py:137} INFO - Index(['     CUST_ID      BALANCE  ...  PRC_FULL_PAYMENT  TENURE'], dtype='object')
[2023-09-17T19:56:09.999+0000] {taskinstance.py:1768} ERROR - Task failed with exception
Traceback (most recent call last):
  File "/home/airflow/.local/lib/python3.7/site-packages/pandas/core/indexes/base.py", line 3361, in get_loc
    return self._engine.get_loc(casted_key)
  File "pandas/_libs/index.pyx", line 76, in pandas._libs.index.IndexEngine.get_loc
  File "pandas/_libs/index.pyx", line 108, in pandas._libs.index.IndexEngine.get_loc
  File "pandas/_libs/hashtable_class_helper.pxi", line 5198, in pandas._libs.hashtable.PyObjectHashTable.get_item
  File "pandas/_libs/hashtable_class_helper.pxi", line 5206, in pandas._libs.hashtable.PyObjectHashTable.get_item
KeyError: ('BALANCE', 'PURCHASES', 'CREDIT_LIMIT')

The above exception was the direct cause of the following exception:

Traceback (most recent call last):
  File "/home/airflow/.local/lib/python3.7/site-packages/airflow/operators/python.py", line 175, in execute
    return_value = self.execute_callable()
  File "/home/airflow/.local/lib/python3.7/site-packages/airflow/operators/python.py", line 192, in execute_callable
    return self.python_callable(*self.op_args, **self.op_kwargs)
  File "/opt/airflow/dags/src/lab2.py", line 36, in data_preprocessing
    clustering_data = data_df["BALANCE", "PURCHASES", "CREDIT_LIMIT"]
  File "/home/airflow/.local/lib/python3.7/site-packages/pandas/core/frame.py", line 3458, in __getitem__
    indexer = self.columns.get_loc(key)
  File "/home/airflow/.local/lib/python3.7/site-packages/pandas/core/indexes/base.py", line 3363, in get_loc
    raise KeyError(key) from err
KeyError: ('BALANCE', 'PURCHASES', 'CREDIT_LIMIT')
[2023-09-17T19:56:10.025+0000] {taskinstance.py:1323} INFO - Marking task as FAILED. dag_id=your_python_dag, task_id=data_preprocessing_task, execution_date=20230917T195603, start_date=20230917T195609, end_date=20230917T195610
[2023-09-17T19:56:10.047+0000] {standard_task_runner.py:105} ERROR - Failed to execute job 75 for task data_preprocessing_task (('BALANCE', 'PURCHASES', 'CREDIT_LIMIT'); 5716)
[2023-09-17T19:56:10.080+0000] {local_task_job.py:208} INFO - Task exited with return code 1
[2023-09-17T19:56:10.114+0000] {taskinstance.py:2578} INFO - 0 downstream tasks scheduled from follow-on schedule check
