[2023-09-30T17:40:50.681+0000] {taskinstance.py:1083} INFO - Dependencies all met for <TaskInstance: your_python_dag.load_data_task manual__2023-09-30T17:40:48.066996+00:00 [queued]>
[2023-09-30T17:40:50.693+0000] {taskinstance.py:1083} INFO - Dependencies all met for <TaskInstance: your_python_dag.load_data_task manual__2023-09-30T17:40:48.066996+00:00 [queued]>
[2023-09-30T17:40:50.693+0000] {taskinstance.py:1279} INFO - 
--------------------------------------------------------------------------------
[2023-09-30T17:40:50.694+0000] {taskinstance.py:1280} INFO - Starting attempt 1 of 1
[2023-09-30T17:40:50.694+0000] {taskinstance.py:1281} INFO - 
--------------------------------------------------------------------------------
[2023-09-30T17:40:50.707+0000] {taskinstance.py:1300} INFO - Executing <Task(PythonOperator): load_data_task> on 2023-09-30 17:40:48.066996+00:00
[2023-09-30T17:40:50.722+0000] {standard_task_runner.py:55} INFO - Started process 4833 to run task
[2023-09-30T17:40:50.727+0000] {standard_task_runner.py:82} INFO - Running: ['***', 'tasks', 'run', 'your_python_dag', 'load_data_task', 'manual__2023-09-30T17:40:48.066996+00:00', '--job-id', '265', '--raw', '--subdir', 'DAGS_FOLDER/***.py', '--cfg-path', '/tmp/tmpg3498whm']
[2023-09-30T17:40:50.731+0000] {standard_task_runner.py:83} INFO - Job 265: Subtask load_data_task
[2023-09-30T17:40:50.834+0000] {task_command.py:388} INFO - Running <TaskInstance: your_python_dag.load_data_task manual__2023-09-30T17:40:48.066996+00:00 [running]> on host 48572125e3d1
[2023-09-30T17:40:50.920+0000] {taskinstance.py:1509} INFO - Exporting the following env vars:
AIRFLOW_CTX_DAG_OWNER=your_name
AIRFLOW_CTX_DAG_ID=your_python_dag
AIRFLOW_CTX_TASK_ID=load_data_task
AIRFLOW_CTX_EXECUTION_DATE=2023-09-30T17:40:48.066996+00:00
AIRFLOW_CTX_TRY_NUMBER=1
AIRFLOW_CTX_DAG_RUN_ID=manual__2023-09-30T17:40:48.066996+00:00
[2023-09-30T17:40:52.067+0000] {logging_mixin.py:137} INFO - GitHub issue logged: https://github.com/DRAJ6/Airflow-GitHub/issues/15
[2023-09-30T17:40:52.068+0000] {taskinstance.py:1768} ERROR - Task failed with exception
Traceback (most recent call last):
  File "/home/airflow/.local/lib/python3.7/site-packages/airflow/operators/python.py", line 175, in execute
    return_value = self.execute_callable()
  File "/home/airflow/.local/lib/python3.7/site-packages/airflow/operators/python.py", line 192, in execute_callable
    return self.python_callable(*self.op_args, **self.op_kwargs)
  File "/opt/airflow/dags/src/lab2.py", line 24, in load_data
    raise e
  File "/opt/airflow/dags/src/lab2.py", line 16, in load_data
    df = pd.read_csv(os.path.join(os.path.dirname(__file__), "../data/files.csv"))
  File "/home/airflow/.local/lib/python3.7/site-packages/pandas/util/_decorators.py", line 311, in wrapper
    return func(*args, **kwargs)
  File "/home/airflow/.local/lib/python3.7/site-packages/pandas/io/parsers/readers.py", line 586, in read_csv
    return _read(filepath_or_buffer, kwds)
  File "/home/airflow/.local/lib/python3.7/site-packages/pandas/io/parsers/readers.py", line 482, in _read
    parser = TextFileReader(filepath_or_buffer, **kwds)
  File "/home/airflow/.local/lib/python3.7/site-packages/pandas/io/parsers/readers.py", line 811, in __init__
    self._engine = self._make_engine(self.engine)
  File "/home/airflow/.local/lib/python3.7/site-packages/pandas/io/parsers/readers.py", line 1040, in _make_engine
    return mapping[engine](self.f, **self.options)  # type: ignore[call-arg]
  File "/home/airflow/.local/lib/python3.7/site-packages/pandas/io/parsers/c_parser_wrapper.py", line 51, in __init__
    self._open_handles(src, kwds)
  File "/home/airflow/.local/lib/python3.7/site-packages/pandas/io/parsers/base_parser.py", line 229, in _open_handles
    errors=kwds.get("encoding_errors", "strict"),
  File "/home/airflow/.local/lib/python3.7/site-packages/pandas/io/common.py", line 707, in get_handle
    newline="",
FileNotFoundError: [Errno 2] No such file or directory: '/opt/airflow/dags/src/../data/files.csv'
[2023-09-30T17:40:52.107+0000] {taskinstance.py:1323} INFO - Marking task as FAILED. dag_id=your_python_dag, task_id=load_data_task, execution_date=20230930T174048, start_date=20230930T174050, end_date=20230930T174052
[2023-09-30T17:40:52.143+0000] {standard_task_runner.py:105} ERROR - Failed to execute job 265 for task load_data_task ([Errno 2] No such file or directory: '/opt/airflow/dags/src/../data/files.csv'; 4833)
[2023-09-30T17:40:52.181+0000] {local_task_job.py:208} INFO - Task exited with return code 1
[2023-09-30T17:40:52.281+0000] {taskinstance.py:2578} INFO - 0 downstream tasks scheduled from follow-on schedule check
