[2023-09-17T21:22:28.693+0000] {taskinstance.py:1083} INFO - Dependencies all met for <TaskInstance: your_python_dag.data_preprocessing_task manual__2023-09-17T21:22:24.641981+00:00 [queued]>
[2023-09-17T21:22:28.710+0000] {taskinstance.py:1083} INFO - Dependencies all met for <TaskInstance: your_python_dag.data_preprocessing_task manual__2023-09-17T21:22:24.641981+00:00 [queued]>
[2023-09-17T21:22:28.711+0000] {taskinstance.py:1279} INFO - 
--------------------------------------------------------------------------------
[2023-09-17T21:22:28.711+0000] {taskinstance.py:1280} INFO - Starting attempt 1 of 1
[2023-09-17T21:22:28.711+0000] {taskinstance.py:1281} INFO - 
--------------------------------------------------------------------------------
[2023-09-17T21:22:28.737+0000] {taskinstance.py:1300} INFO - Executing <Task(PythonOperator): data_preprocessing_task> on 2023-09-17 21:22:24.641981+00:00
[2023-09-17T21:22:28.764+0000] {standard_task_runner.py:55} INFO - Started process 650 to run task
[2023-09-17T21:22:28.769+0000] {standard_task_runner.py:82} INFO - Running: ['***', 'tasks', 'run', 'your_python_dag', 'data_preprocessing_task', 'manual__2023-09-17T21:22:24.641981+00:00', '--job-id', '117', '--raw', '--subdir', 'DAGS_FOLDER/***.py', '--cfg-path', '/tmp/tmp6n3o9zql']
[2023-09-17T21:22:28.771+0000] {standard_task_runner.py:83} INFO - Job 117: Subtask data_preprocessing_task
[2023-09-17T21:22:28.830+0000] {task_command.py:388} INFO - Running <TaskInstance: your_python_dag.data_preprocessing_task manual__2023-09-17T21:22:24.641981+00:00 [running]> on host b55550b47356
[2023-09-17T21:22:29.050+0000] {taskinstance.py:1509} INFO - Exporting the following env vars:
AIRFLOW_CTX_DAG_OWNER=your_name
AIRFLOW_CTX_DAG_ID=your_python_dag
AIRFLOW_CTX_TASK_ID=data_preprocessing_task
AIRFLOW_CTX_EXECUTION_DATE=2023-09-17T21:22:24.641981+00:00
AIRFLOW_CTX_TRY_NUMBER=1
AIRFLOW_CTX_DAG_RUN_ID=manual__2023-09-17T21:22:24.641981+00:00
[2023-09-17T21:22:29.061+0000] {logging_mixin.py:137} INFO - <class 'pandas.core.frame.DataFrame'>
[2023-09-17T21:22:29.061+0000] {logging_mixin.py:137} INFO - ahbd
[2023-09-17T21:22:29.075+0000] {logging_mixin.py:137} INFO -      CUST_ID      BALANCE  ...  PRC_FULL_PAYMENT  TENURE
0     C10001    40.900749  ...          0.000000      12
1     C10002  3202.467416  ...          0.222222      12
2     C10003  2495.148862  ...          0.000000      12
4     C10005   817.714335  ...          0.000000      12
5     C10006  1809.828751  ...          0.000000      12
...      ...          ...  ...               ...     ...
8943  C19184     5.871712  ...          0.000000       6
8945  C19186    28.493517  ...          0.500000       6
8947  C19188    23.398673  ...          0.250000       6
8948  C19189    13.457564  ...          0.250000       6
8949  C19190   372.708075  ...          0.000000       6

[8636 rows x 18 columns]
[2023-09-17T21:22:29.076+0000] {logging_mixin.py:137} INFO - Index(['CUST_ID', 'BALANCE', 'BALANCE_FREQUENCY', 'PURCHASES',
       'ONEOFF_PURCHASES', 'INSTALLMENTS_PURCHASES', 'CASH_ADVANCE',
       'PURCHASES_FREQUENCY', 'ONEOFF_PURCHASES_FREQUENCY',
       'PURCHASES_INSTALLMENTS_FREQUENCY', 'CASH_ADVANCE_FREQUENCY',
       'CASH_ADVANCE_TRX', 'PURCHASES_TRX', 'CREDIT_LIMIT', 'PAYMENTS',
       'MINIMUM_PAYMENTS', 'PRC_FULL_PAYMENT', 'TENURE'],
      dtype='object')
[2023-09-17T21:22:29.076+0000] {logging_mixin.py:137} INFO - <class 'pandas.core.frame.DataFrame'>
[2023-09-17T21:22:29.076+0000] {taskinstance.py:1768} ERROR - Task failed with exception
Traceback (most recent call last):
  File "/home/airflow/.local/lib/python3.7/site-packages/pandas/core/indexes/base.py", line 3361, in get_loc
    return self._engine.get_loc(casted_key)
  File "pandas/_libs/index.pyx", line 76, in pandas._libs.index.IndexEngine.get_loc
  File "pandas/_libs/index.pyx", line 108, in pandas._libs.index.IndexEngine.get_loc
  File "pandas/_libs/hashtable_class_helper.pxi", line 5198, in pandas._libs.hashtable.PyObjectHashTable.get_item
  File "pandas/_libs/hashtable_class_helper.pxi", line 5206, in pandas._libs.hashtable.PyObjectHashTable.get_item
KeyError: ('BALANCE', 'PURCHASES', 'CREDIT_LIMIT')

The above exception was the direct cause of the following exception:

Traceback (most recent call last):
  File "/home/airflow/.local/lib/python3.7/site-packages/airflow/operators/python.py", line 175, in execute
    return_value = self.execute_callable()
  File "/home/airflow/.local/lib/python3.7/site-packages/airflow/operators/python.py", line 192, in execute_callable
    return self.python_callable(*self.op_args, **self.op_kwargs)
  File "/opt/airflow/dags/src/lab2.py", line 49, in data_preprocessing
    clustering_data = df["BALANCE", "PURCHASES", "CREDIT_LIMIT"]
  File "/home/airflow/.local/lib/python3.7/site-packages/pandas/core/frame.py", line 3458, in __getitem__
    indexer = self.columns.get_loc(key)
  File "/home/airflow/.local/lib/python3.7/site-packages/pandas/core/indexes/base.py", line 3363, in get_loc
    raise KeyError(key) from err
KeyError: ('BALANCE', 'PURCHASES', 'CREDIT_LIMIT')
[2023-09-17T21:22:29.085+0000] {taskinstance.py:1323} INFO - Marking task as FAILED. dag_id=your_python_dag, task_id=data_preprocessing_task, execution_date=20230917T212224, start_date=20230917T212228, end_date=20230917T212229
[2023-09-17T21:22:29.093+0000] {standard_task_runner.py:105} ERROR - Failed to execute job 117 for task data_preprocessing_task (('BALANCE', 'PURCHASES', 'CREDIT_LIMIT'); 650)
[2023-09-17T21:22:29.143+0000] {local_task_job.py:208} INFO - Task exited with return code 1
[2023-09-17T21:22:29.174+0000] {taskinstance.py:2578} INFO - 0 downstream tasks scheduled from follow-on schedule check
