[2023-10-01T03:31:50.218+0000] {taskinstance.py:1083} INFO - Dependencies all met for <TaskInstance: Airflow-GitHub.build_save_model_task manual__2023-10-01T03:31:35.975703+00:00 [queued]>
[2023-10-01T03:31:50.272+0000] {taskinstance.py:1083} INFO - Dependencies all met for <TaskInstance: Airflow-GitHub.build_save_model_task manual__2023-10-01T03:31:35.975703+00:00 [queued]>
[2023-10-01T03:31:50.277+0000] {taskinstance.py:1279} INFO - 
--------------------------------------------------------------------------------
[2023-10-01T03:31:50.278+0000] {taskinstance.py:1280} INFO - Starting attempt 1 of 1
[2023-10-01T03:31:50.278+0000] {taskinstance.py:1281} INFO - 
--------------------------------------------------------------------------------
[2023-10-01T03:31:50.317+0000] {taskinstance.py:1300} INFO - Executing <Task(PythonOperator): build_save_model_task> on 2023-10-01 03:31:35.975703+00:00
[2023-10-01T03:31:50.343+0000] {standard_task_runner.py:55} INFO - Started process 2259 to run task
[2023-10-01T03:31:50.355+0000] {standard_task_runner.py:82} INFO - Running: ['***', 'tasks', 'run', 'Airflow-GitHub', 'build_save_model_task', 'manual__2023-10-01T03:31:35.975703+00:00', '--job-id', '307', '--raw', '--subdir', 'DAGS_FOLDER/***.py', '--cfg-path', '/tmp/tmprlufybyy']
[2023-10-01T03:31:50.360+0000] {standard_task_runner.py:83} INFO - Job 307: Subtask build_save_model_task
[2023-10-01T03:31:50.782+0000] {task_command.py:388} INFO - Running <TaskInstance: Airflow-GitHub.build_save_model_task manual__2023-10-01T03:31:35.975703+00:00 [running]> on host 434a62d4e45a
[2023-10-01T03:31:51.169+0000] {taskinstance.py:1509} INFO - Exporting the following env vars:
AIRFLOW_CTX_DAG_OWNER=Dheeraj
AIRFLOW_CTX_DAG_ID=Airflow-GitHub
AIRFLOW_CTX_TASK_ID=build_save_model_task
AIRFLOW_CTX_EXECUTION_DATE=2023-10-01T03:31:35.975703+00:00
AIRFLOW_CTX_TRY_NUMBER=1
AIRFLOW_CTX_DAG_RUN_ID=manual__2023-10-01T03:31:35.975703+00:00
[2023-10-01T03:31:51.609+0000] {warnings.py:110} WARNING - /home/***/.local/lib/python3.7/site-packages/joblib/parallel.py:1333: UserWarning: Loky-backed parallel loops cannot be called in a multiprocessing, setting n_jobs=1
  **self._backend_args)

[2023-10-01T03:31:51.610+0000] {logging_mixin.py:137} INFO - Fitting 10 folds for each of 64 candidates, totalling 640 fits
[2023-10-01T03:32:08.690+0000] {base_job.py:243} ERROR - LocalTaskJob heartbeat got an exception
Traceback (most recent call last):
  File "/home/airflow/.local/lib/python3.7/site-packages/sqlalchemy/engine/base.py", line 3361, in _wrap_pool_connect
    return fn()
  File "/home/airflow/.local/lib/python3.7/site-packages/sqlalchemy/pool/base.py", line 327, in connect
    return _ConnectionFairy._checkout(self)
  File "/home/airflow/.local/lib/python3.7/site-packages/sqlalchemy/pool/base.py", line 894, in _checkout
    fairy = _ConnectionRecord.checkout(pool)
  File "/home/airflow/.local/lib/python3.7/site-packages/sqlalchemy/pool/base.py", line 493, in checkout
    rec = pool._do_get()
  File "/home/airflow/.local/lib/python3.7/site-packages/sqlalchemy/pool/impl.py", line 256, in _do_get
    return self._create_connection()
  File "/home/airflow/.local/lib/python3.7/site-packages/sqlalchemy/pool/base.py", line 273, in _create_connection
    return _ConnectionRecord(self)
  File "/home/airflow/.local/lib/python3.7/site-packages/sqlalchemy/pool/base.py", line 388, in __init__
    self.__connect()
  File "/home/airflow/.local/lib/python3.7/site-packages/sqlalchemy/pool/base.py", line 691, in __connect
    pool.logger.debug("Error on connect(): %s", e)
  File "/home/airflow/.local/lib/python3.7/site-packages/sqlalchemy/util/langhelpers.py", line 72, in __exit__
    with_traceback=exc_tb,
  File "/home/airflow/.local/lib/python3.7/site-packages/sqlalchemy/util/compat.py", line 211, in raise_
    raise exception
  File "/home/airflow/.local/lib/python3.7/site-packages/sqlalchemy/pool/base.py", line 686, in __connect
    self.dbapi_connection = connection = pool._invoke_creator(self)
  File "/home/airflow/.local/lib/python3.7/site-packages/sqlalchemy/engine/create.py", line 578, in connect
    return dialect.connect(*cargs, **cparams)
  File "/home/airflow/.local/lib/python3.7/site-packages/sqlalchemy/engine/default.py", line 598, in connect
    return self.dbapi.connect(*cargs, **cparams)
  File "/home/airflow/.local/lib/python3.7/site-packages/psycopg2/__init__.py", line 122, in connect
    conn = _connect(dsn, connection_factory=connection_factory, **kwasync)
psycopg2.OperationalError: could not translate host name "postgres" to address: Temporary failure in name resolution


The above exception was the direct cause of the following exception:

Traceback (most recent call last):
  File "/home/airflow/.local/lib/python3.7/site-packages/airflow/jobs/base_job.py", line 215, in heartbeat
    session.merge(self)
  File "/home/airflow/.local/lib/python3.7/site-packages/sqlalchemy/orm/session.py", line 3057, in merge
    _resolve_conflict_map=_resolve_conflict_map,
  File "/home/airflow/.local/lib/python3.7/site-packages/sqlalchemy/orm/session.py", line 3135, in _merge
    options=options,
  File "/home/airflow/.local/lib/python3.7/site-packages/sqlalchemy/orm/session.py", line 2856, in get
    execution_options=execution_options,
  File "/home/airflow/.local/lib/python3.7/site-packages/sqlalchemy/orm/session.py", line 2974, in _get_impl
    load_options=load_options,
  File "/home/airflow/.local/lib/python3.7/site-packages/sqlalchemy/orm/loading.py", line 534, in load_on_pk_identity
    bind_arguments=bind_arguments,
  File "/home/airflow/.local/lib/python3.7/site-packages/sqlalchemy/orm/session.py", line 1713, in execute
    conn = self._connection_for_bind(bind)
  File "/home/airflow/.local/lib/python3.7/site-packages/sqlalchemy/orm/session.py", line 1553, in _connection_for_bind
    engine, execution_options
  File "/home/airflow/.local/lib/python3.7/site-packages/sqlalchemy/orm/session.py", line 747, in _connection_for_bind
    conn = bind.connect()
  File "/home/airflow/.local/lib/python3.7/site-packages/sqlalchemy/engine/base.py", line 3315, in connect
    return self._connection_cls(self, close_with_result=close_with_result)
  File "/home/airflow/.local/lib/python3.7/site-packages/sqlalchemy/engine/base.py", line 96, in __init__
    else engine.raw_connection()
  File "/home/airflow/.local/lib/python3.7/site-packages/sqlalchemy/engine/base.py", line 3394, in raw_connection
    return self._wrap_pool_connect(self.pool.connect, _connection)
  File "/home/airflow/.local/lib/python3.7/site-packages/sqlalchemy/engine/base.py", line 3365, in _wrap_pool_connect
    e, dialect, self
  File "/home/airflow/.local/lib/python3.7/site-packages/sqlalchemy/engine/base.py", line 2199, in _handle_dbapi_exception_noconnection
    sqlalchemy_exception, with_traceback=exc_info[2], from_=e
  File "/home/airflow/.local/lib/python3.7/site-packages/sqlalchemy/util/compat.py", line 211, in raise_
    raise exception
  File "/home/airflow/.local/lib/python3.7/site-packages/sqlalchemy/engine/base.py", line 3361, in _wrap_pool_connect
    return fn()
  File "/home/airflow/.local/lib/python3.7/site-packages/sqlalchemy/pool/base.py", line 327, in connect
    return _ConnectionFairy._checkout(self)
  File "/home/airflow/.local/lib/python3.7/site-packages/sqlalchemy/pool/base.py", line 894, in _checkout
    fairy = _ConnectionRecord.checkout(pool)
  File "/home/airflow/.local/lib/python3.7/site-packages/sqlalchemy/pool/base.py", line 493, in checkout
    rec = pool._do_get()
  File "/home/airflow/.local/lib/python3.7/site-packages/sqlalchemy/pool/impl.py", line 256, in _do_get
    return self._create_connection()
  File "/home/airflow/.local/lib/python3.7/site-packages/sqlalchemy/pool/base.py", line 273, in _create_connection
    return _ConnectionRecord(self)
  File "/home/airflow/.local/lib/python3.7/site-packages/sqlalchemy/pool/base.py", line 388, in __init__
    self.__connect()
  File "/home/airflow/.local/lib/python3.7/site-packages/sqlalchemy/pool/base.py", line 691, in __connect
    pool.logger.debug("Error on connect(): %s", e)
  File "/home/airflow/.local/lib/python3.7/site-packages/sqlalchemy/util/langhelpers.py", line 72, in __exit__
    with_traceback=exc_tb,
  File "/home/airflow/.local/lib/python3.7/site-packages/sqlalchemy/util/compat.py", line 211, in raise_
    raise exception
  File "/home/airflow/.local/lib/python3.7/site-packages/sqlalchemy/pool/base.py", line 686, in __connect
    self.dbapi_connection = connection = pool._invoke_creator(self)
  File "/home/airflow/.local/lib/python3.7/site-packages/sqlalchemy/engine/create.py", line 578, in connect
    return dialect.connect(*cargs, **cparams)
  File "/home/airflow/.local/lib/python3.7/site-packages/sqlalchemy/engine/default.py", line 598, in connect
    return self.dbapi.connect(*cargs, **cparams)
  File "/home/airflow/.local/lib/python3.7/site-packages/psycopg2/__init__.py", line 122, in connect
    conn = _connect(dsn, connection_factory=connection_factory, **kwasync)
sqlalchemy.exc.OperationalError: (psycopg2.OperationalError) could not translate host name "postgres" to address: Temporary failure in name resolution

(Background on this error at: https://sqlalche.me/e/14/e3q8)
[2023-10-01T03:32:33.590+0000] {logging_mixin.py:137} INFO - Best parameters: {'C': 0.6, 'class_weight': {1: 0.5, 0: 0.5}, 'penalty': 'l2', 'solver': 'saga'}
[2023-10-01T03:32:33.612+0000] {python.py:177} INFO - Done. Returned value was: None
[2023-10-01T03:32:33.648+0000] {taskinstance.py:1323} INFO - Marking task as SUCCESS. dag_id=Airflow-GitHub, task_id=build_save_model_task, execution_date=20231001T033135, start_date=20231001T033150, end_date=20231001T033233
[2023-10-01T03:32:33.755+0000] {local_task_job.py:208} INFO - Task exited with return code 0
[2023-10-01T03:32:33.848+0000] {taskinstance.py:2578} INFO - 1 downstream tasks scheduled from follow-on schedule check
