[2023-09-17T19:05:12.670+0000] {taskinstance.py:1083} INFO - Dependencies all met for <TaskInstance: your_python_dag.load_data_task manual__2023-09-17T19:05:09.735472+00:00 [queued]>
[2023-09-17T19:05:12.680+0000] {taskinstance.py:1083} INFO - Dependencies all met for <TaskInstance: your_python_dag.load_data_task manual__2023-09-17T19:05:09.735472+00:00 [queued]>
[2023-09-17T19:05:12.680+0000] {taskinstance.py:1279} INFO - 
--------------------------------------------------------------------------------
[2023-09-17T19:05:12.680+0000] {taskinstance.py:1280} INFO - Starting attempt 1 of 1
[2023-09-17T19:05:12.680+0000] {taskinstance.py:1281} INFO - 
--------------------------------------------------------------------------------
[2023-09-17T19:05:12.691+0000] {taskinstance.py:1300} INFO - Executing <Task(PythonOperator): load_data_task> on 2023-09-17 19:05:09.735472+00:00
[2023-09-17T19:05:12.701+0000] {standard_task_runner.py:55} INFO - Started process 2803 to run task
[2023-09-17T19:05:12.706+0000] {standard_task_runner.py:82} INFO - Running: ['***', 'tasks', 'run', 'your_python_dag', 'load_data_task', 'manual__2023-09-17T19:05:09.735472+00:00', '--job-id', '44', '--raw', '--subdir', 'DAGS_FOLDER/***.py', '--cfg-path', '/tmp/tmp9jbdvd1e']
[2023-09-17T19:05:12.711+0000] {standard_task_runner.py:83} INFO - Job 44: Subtask load_data_task
[2023-09-17T19:05:12.786+0000] {task_command.py:388} INFO - Running <TaskInstance: your_python_dag.load_data_task manual__2023-09-17T19:05:09.735472+00:00 [running]> on host 80c059a34b8e
[2023-09-17T19:05:12.908+0000] {taskinstance.py:1509} INFO - Exporting the following env vars:
AIRFLOW_CTX_DAG_OWNER=your_name
AIRFLOW_CTX_DAG_ID=your_python_dag
AIRFLOW_CTX_TASK_ID=load_data_task
AIRFLOW_CTX_EXECUTION_DATE=2023-09-17T19:05:09.735472+00:00
AIRFLOW_CTX_TRY_NUMBER=1
AIRFLOW_CTX_DAG_RUN_ID=manual__2023-09-17T19:05:09.735472+00:00
[2023-09-17T19:05:12.921+0000] {taskinstance.py:1768} ERROR - Task failed with exception
Traceback (most recent call last):
  File "/home/airflow/.local/lib/python3.7/site-packages/airflow/operators/python.py", line 175, in execute
    return_value = self.execute_callable()
  File "/home/airflow/.local/lib/python3.7/site-packages/airflow/operators/python.py", line 192, in execute_callable
    return self.python_callable(*self.op_args, **self.op_kwargs)
  File "/opt/airflow/dags/src/lab2.py", line 18, in load_data
    data = pd.read_csv(path)
  File "/home/airflow/.local/lib/python3.7/site-packages/pandas/util/_decorators.py", line 311, in wrapper
    return func(*args, **kwargs)
  File "/home/airflow/.local/lib/python3.7/site-packages/pandas/io/parsers/readers.py", line 586, in read_csv
    return _read(filepath_or_buffer, kwds)
  File "/home/airflow/.local/lib/python3.7/site-packages/pandas/io/parsers/readers.py", line 482, in _read
    parser = TextFileReader(filepath_or_buffer, **kwds)
  File "/home/airflow/.local/lib/python3.7/site-packages/pandas/io/parsers/readers.py", line 811, in __init__
    self._engine = self._make_engine(self.engine)
  File "/home/airflow/.local/lib/python3.7/site-packages/pandas/io/parsers/readers.py", line 1040, in _make_engine
    return mapping[engine](self.f, **self.options)  # type: ignore[call-arg]
  File "/home/airflow/.local/lib/python3.7/site-packages/pandas/io/parsers/c_parser_wrapper.py", line 51, in __init__
    self._open_handles(src, kwds)
  File "/home/airflow/.local/lib/python3.7/site-packages/pandas/io/parsers/base_parser.py", line 229, in _open_handles
    errors=kwds.get("encoding_errors", "strict"),
  File "/home/airflow/.local/lib/python3.7/site-packages/pandas/io/common.py", line 707, in get_handle
    newline="",
FileNotFoundError: [Errno 2] No such file or directory: '/Users/dheeraj/file.csv'
[2023-09-17T19:05:12.937+0000] {taskinstance.py:1323} INFO - Marking task as FAILED. dag_id=your_python_dag, task_id=load_data_task, execution_date=20230917T190509, start_date=20230917T190512, end_date=20230917T190512
[2023-09-17T19:05:12.954+0000] {standard_task_runner.py:105} ERROR - Failed to execute job 44 for task load_data_task ([Errno 2] No such file or directory: '/Users/dheeraj/file.csv'; 2803)
[2023-09-17T19:05:12.998+0000] {local_task_job.py:208} INFO - Task exited with return code 1
[2023-09-17T19:05:13.036+0000] {taskinstance.py:2578} INFO - 0 downstream tasks scheduled from follow-on schedule check
