[2023-09-17T19:53:22.807+0000] {taskinstance.py:1083} INFO - Dependencies all met for <TaskInstance: your_python_dag.data_preprocessing_task manual__2023-09-17T19:53:13.494966+00:00 [queued]>
[2023-09-17T19:53:22.815+0000] {taskinstance.py:1083} INFO - Dependencies all met for <TaskInstance: your_python_dag.data_preprocessing_task manual__2023-09-17T19:53:13.494966+00:00 [queued]>
[2023-09-17T19:53:22.815+0000] {taskinstance.py:1279} INFO - 
--------------------------------------------------------------------------------
[2023-09-17T19:53:22.815+0000] {taskinstance.py:1280} INFO - Starting attempt 1 of 1
[2023-09-17T19:53:22.815+0000] {taskinstance.py:1281} INFO - 
--------------------------------------------------------------------------------
[2023-09-17T19:53:22.828+0000] {taskinstance.py:1300} INFO - Executing <Task(PythonOperator): data_preprocessing_task> on 2023-09-17 19:53:13.494966+00:00
[2023-09-17T19:53:22.843+0000] {standard_task_runner.py:55} INFO - Started process 5545 to run task
[2023-09-17T19:53:22.848+0000] {standard_task_runner.py:82} INFO - Running: ['***', 'tasks', 'run', 'your_python_dag', 'data_preprocessing_task', 'manual__2023-09-17T19:53:13.494966+00:00', '--job-id', '71', '--raw', '--subdir', 'DAGS_FOLDER/***.py', '--cfg-path', '/tmp/tmpkpj1z9go']
[2023-09-17T19:53:22.851+0000] {standard_task_runner.py:83} INFO - Job 71: Subtask data_preprocessing_task
[2023-09-17T19:53:22.939+0000] {task_command.py:388} INFO - Running <TaskInstance: your_python_dag.data_preprocessing_task manual__2023-09-17T19:53:13.494966+00:00 [running]> on host 80c059a34b8e
[2023-09-17T19:53:23.103+0000] {taskinstance.py:1509} INFO - Exporting the following env vars:
AIRFLOW_CTX_DAG_OWNER=your_name
AIRFLOW_CTX_DAG_ID=your_python_dag
AIRFLOW_CTX_TASK_ID=data_preprocessing_task
AIRFLOW_CTX_EXECUTION_DATE=2023-09-17T19:53:13.494966+00:00
AIRFLOW_CTX_TRY_NUMBER=1
AIRFLOW_CTX_DAG_RUN_ID=manual__2023-09-17T19:53:13.494966+00:00
[2023-09-17T19:53:23.106+0000] {logging_mixin.py:137} INFO - <class 'str'>
[2023-09-17T19:53:23.106+0000] {logging_mixin.py:137} INFO - ahbd
[2023-09-17T19:53:23.107+0000] {logging_mixin.py:137} INFO -      CUST_ID      BALANCE  ...  PRC_FULL_PAYMENT  TENURE
0     C10001    40.900749  ...          0.000000      12
1     C10002  3202.467416  ...          0.222222      12
2     C10003  2495.148862  ...          0.000000      12
3     C10004  1666.670542  ...          0.000000      12
4     C10005   817.714335  ...          0.000000      12
...      ...          ...  ...               ...     ...
8945  C19186    28.493517  ...          0.500000       6
8946  C19187    19.183215  ...          0.000000       6
8947  C19188    23.398673  ...          0.250000       6
8948  C19189    13.457564  ...          0.250000       6
8949  C19190   372.708075  ...          0.000000       6

[8950 rows x 18 columns]
[2023-09-17T19:53:23.120+0000] {taskinstance.py:1768} ERROR - Task failed with exception
Traceback (most recent call last):
  File "/home/airflow/.local/lib/python3.7/site-packages/airflow/operators/python.py", line 175, in execute
    return_value = self.execute_callable()
  File "/home/airflow/.local/lib/python3.7/site-packages/airflow/operators/python.py", line 192, in execute_callable
    return self.python_callable(*self.op_args, **self.op_kwargs)
  File "/opt/airflow/dags/src/lab2.py", line 35, in data_preprocessing
    clustering_data = data_df[["BALANCE", "PURCHASES", "CREDIT_LIMIT"]]
  File "/home/airflow/.local/lib/python3.7/site-packages/pandas/core/frame.py", line 3464, in __getitem__
    indexer = self.loc._get_listlike_indexer(key, axis=1)[1]
  File "/home/airflow/.local/lib/python3.7/site-packages/pandas/core/indexing.py", line 1314, in _get_listlike_indexer
    self._validate_read_indexer(keyarr, indexer, axis)
  File "/home/airflow/.local/lib/python3.7/site-packages/pandas/core/indexing.py", line 1374, in _validate_read_indexer
    raise KeyError(f"None of [{key}] are in the [{axis_name}]")
KeyError: "None of [Index(['BALANCE', 'PURCHASES', 'CREDIT_LIMIT'], dtype='object')] are in the [columns]"
[2023-09-17T19:53:23.140+0000] {taskinstance.py:1323} INFO - Marking task as FAILED. dag_id=your_python_dag, task_id=data_preprocessing_task, execution_date=20230917T195313, start_date=20230917T195322, end_date=20230917T195323
[2023-09-17T19:53:23.150+0000] {standard_task_runner.py:105} ERROR - Failed to execute job 71 for task data_preprocessing_task ("None of [Index(['BALANCE', 'PURCHASES', 'CREDIT_LIMIT'], dtype='object')] are in the [columns]"; 5545)
[2023-09-17T19:53:23.181+0000] {local_task_job.py:208} INFO - Task exited with return code 1
[2023-09-17T19:53:23.239+0000] {taskinstance.py:2578} INFO - 0 downstream tasks scheduled from follow-on schedule check
