[2023-09-17T18:33:09.140+0000] {taskinstance.py:1083} INFO - Dependencies all met for <TaskInstance: your_python_dag.load_data_task manual__2023-09-17T18:28:05.273222+00:00 [queued]>
[2023-09-17T18:33:09.146+0000] {taskinstance.py:1083} INFO - Dependencies all met for <TaskInstance: your_python_dag.load_data_task manual__2023-09-17T18:28:05.273222+00:00 [queued]>
[2023-09-17T18:33:09.147+0000] {taskinstance.py:1279} INFO - 
--------------------------------------------------------------------------------
[2023-09-17T18:33:09.147+0000] {taskinstance.py:1280} INFO - Starting attempt 2 of 2
[2023-09-17T18:33:09.147+0000] {taskinstance.py:1281} INFO - 
--------------------------------------------------------------------------------
[2023-09-17T18:33:09.155+0000] {taskinstance.py:1300} INFO - Executing <Task(PythonOperator): load_data_task> on 2023-09-17 18:28:05.273222+00:00
[2023-09-17T18:33:09.171+0000] {standard_task_runner.py:55} INFO - Started process 824 to run task
[2023-09-17T18:33:09.176+0000] {standard_task_runner.py:82} INFO - Running: ['***', 'tasks', 'run', 'your_python_dag', 'load_data_task', 'manual__2023-09-17T18:28:05.273222+00:00', '--job-id', '29', '--raw', '--subdir', 'DAGS_FOLDER/***.py', '--cfg-path', '/tmp/tmpu4nk8lgm']
[2023-09-17T18:33:09.186+0000] {standard_task_runner.py:83} INFO - Job 29: Subtask load_data_task
[2023-09-17T18:33:09.245+0000] {task_command.py:388} INFO - Running <TaskInstance: your_python_dag.load_data_task manual__2023-09-17T18:28:05.273222+00:00 [running]> on host 80c059a34b8e
[2023-09-17T18:33:09.307+0000] {taskinstance.py:1509} INFO - Exporting the following env vars:
AIRFLOW_CTX_DAG_OWNER=your_name
AIRFLOW_CTX_DAG_ID=your_python_dag
AIRFLOW_CTX_TASK_ID=load_data_task
AIRFLOW_CTX_EXECUTION_DATE=2023-09-17T18:28:05.273222+00:00
AIRFLOW_CTX_TRY_NUMBER=2
AIRFLOW_CTX_DAG_RUN_ID=manual__2023-09-17T18:28:05.273222+00:00
[2023-09-17T18:33:09.310+0000] {taskinstance.py:1768} ERROR - Task failed with exception
Traceback (most recent call last):
  File "/home/airflow/.local/lib/python3.7/site-packages/airflow/operators/python.py", line 175, in execute
    return_value = self.execute_callable()
  File "/home/airflow/.local/lib/python3.7/site-packages/airflow/operators/python.py", line 192, in execute_callable
    return self.python_callable(*self.op_args, **self.op_kwargs)
  File "/opt/airflow/dags/src/lab2.py", line 16, in load_data
    data = pd.read_csv("/Users/dheeraj/app/dags/data/file.csv")
  File "/home/airflow/.local/lib/python3.7/site-packages/pandas/util/_decorators.py", line 311, in wrapper
    return func(*args, **kwargs)
  File "/home/airflow/.local/lib/python3.7/site-packages/pandas/io/parsers/readers.py", line 586, in read_csv
    return _read(filepath_or_buffer, kwds)
  File "/home/airflow/.local/lib/python3.7/site-packages/pandas/io/parsers/readers.py", line 482, in _read
    parser = TextFileReader(filepath_or_buffer, **kwds)
  File "/home/airflow/.local/lib/python3.7/site-packages/pandas/io/parsers/readers.py", line 811, in __init__
    self._engine = self._make_engine(self.engine)
  File "/home/airflow/.local/lib/python3.7/site-packages/pandas/io/parsers/readers.py", line 1040, in _make_engine
    return mapping[engine](self.f, **self.options)  # type: ignore[call-arg]
  File "/home/airflow/.local/lib/python3.7/site-packages/pandas/io/parsers/c_parser_wrapper.py", line 51, in __init__
    self._open_handles(src, kwds)
  File "/home/airflow/.local/lib/python3.7/site-packages/pandas/io/parsers/base_parser.py", line 229, in _open_handles
    errors=kwds.get("encoding_errors", "strict"),
  File "/home/airflow/.local/lib/python3.7/site-packages/pandas/io/common.py", line 707, in get_handle
    newline="",
FileNotFoundError: [Errno 2] No such file or directory: '/Users/dheeraj/app/dags/data/file.csv'
[2023-09-17T18:33:09.319+0000] {taskinstance.py:1323} INFO - Marking task as FAILED. dag_id=your_python_dag, task_id=load_data_task, execution_date=20230917T182805, start_date=20230917T183309, end_date=20230917T183309
[2023-09-17T18:33:09.327+0000] {standard_task_runner.py:105} ERROR - Failed to execute job 29 for task load_data_task ([Errno 2] No such file or directory: '/Users/dheeraj/app/dags/data/file.csv'; 824)
[2023-09-17T18:33:09.348+0000] {local_task_job.py:208} INFO - Task exited with return code 1
[2023-09-17T18:33:09.370+0000] {taskinstance.py:2578} INFO - 0 downstream tasks scheduled from follow-on schedule check
